<?xml version="1.0" ?>
<!-- =================================================================================== -->
<!-- |    This document was autogenerated by xacro from mini_servo.urdf.xacro          | -->
<!-- |    EDITING THIS FILE BY HAND IS NOT RECOMMENDED                                 | -->
<!-- =================================================================================== -->
<robot name="mini_servo" xmlns:xacro="http://www.ros.org/wiki/xacro">
  <material name="Black">
    <color rgba="0.0 0.0 0.0 1.0"/>
  </material>
  <material name="Blue">
    <color rgba="0.0 0.0 0.8 1.0"/>
  </material>
  <material name="Green">
    <color rgba="0.0 0.8 0.0 1.0"/>
  </material>
  <material name="Grey">
    <color rgba="0.4 0.4 0.4 1.0"/>
  </material>
  <material name="Orange">
    <color rgba="1.0 0.423529411765 0.0392156862745 1.0"/>
  </material>
  <material name="Brown">
    <color rgba="0.870588235294 0.811764705882 0.764705882353 1.0"/>
  </material>
  <material name="Red">
    <color rgba="0.8 0.0 0.0 1.0"/>
  </material>
  <material name="White">
    <color rgba="1.0 1.0 1.0 1.0"/>
  </material>
  <!-- Fix to world, change if mounted to something -->
  <link name="world"/>
  <!--joint between {parent} and link_0-->
  <joint name="world_mini_servo_joint" type="fixed">
    <origin rpy="0 0 0" xyz="0 0 0"/>
    <parent link="world"/>
    <child link="mini_servo_link_0"/>
  </joint>
  <link name="mini_servo_link_0">
    <inertial>
      <origin rpy="0 0 0" xyz="0 0 0.00725"/>
      <mass value="0.050"/>
      <inertia ixx="0.001" ixy="0" ixz="0" iyy="0.001" iyz="0" izz="0.001"/>
    </inertial>
    <visual>
      <origin rpy="0 0 0" xyz="0 0 0"/>
      <geometry>
        <mesh filename="package://mini_servo_model/urdf/meshes/visual/link_0.stl" scale="0.001 0.001 0.001"/>
      </geometry>
      <material name="Grey"/>
    </visual>
    <collision>
      <origin rpy="0 0 0" xyz="0 0 0"/>
      <geometry>
        <mesh filename="package://mini_servo_model/urdf/meshes/collision/link_0.stl" scale="0.001 0.001 0.001"/>
      </geometry>
      <material name="Grey"/>
    </collision>
    <self_collision_checking>
      <origin rpy="0 0 0" xyz="0 0 0"/>
      <geometry>
        <capsule length="0.25" radius="0.15"/>
      </geometry>
    </self_collision_checking>
  </link>
  <!-- joint between link_0 and link_1 -->
  <joint name="mini_servo_joint_1" type="revolute">
    <parent link="mini_servo_link_0"/>
    <child link="mini_servo_link_1"/>
    <origin rpy="0 0 0" xyz="0 0 0.0145"/>
    <axis xyz="0 0 1"/>
    <limit effort="300" lower="-2.16420827247" upper="1.57079632679" velocity="10"/>
    <safety_controller k_position="100" k_velocity="2" soft_lower_limit="-2.14675497995" soft_upper_limit="1.55334303427"/>
    <dynamics damping="0.5"/>
  </joint>
  <link name="mini_servo_link_1">
    <inertial>
      <origin rpy="0 0 0" xyz="0 0.0175 0.045"/>
      <mass value="0.050"/>
      <inertia ixx="0.005" ixy="0" ixz="0" iyy="0.005" iyz="0" izz="0.005"/>
    </inertial>
    <visual>
      <origin rpy="0 0 3.14159265359" xyz="0 0 0"/>
      <geometry>
        <mesh filename="package://mini_servo_model/urdf/meshes/visual/link_1.stl" scale="0.001 0.001 0.001"/>
      </geometry>
      <material name="Grey"/>
    </visual>
    <collision>
      <origin rpy="0 0 3.14159265359" xyz="0 0 0"/>
      <geometry>
        <mesh filename="package://mini_servo_model/urdf/meshes/collision/link_1.stl" scale="0.001 0.001 0.001"/>
      </geometry>
      <material name="Grey"/>
    </collision>
  </link>
  <!-- joint between link_1 and link_2 -->
  <joint name="mini_servo_joint_2" type="revolute">
    <parent link="mini_servo_link_1"/>
    <child link="mini_servo_link_2"/>
    <origin rpy="-1.57079632679 3.14159265359 0" xyz="0.035 0 0.090"/>
    <axis xyz="0 0 1"/>
    <limit effort="300" lower="-1.3962634016" upper="1.09955742876" velocity="10"/>
    <safety_controller k_position="100" k_velocity="2" soft_lower_limit="-1.37881010908" soft_upper_limit="1.08210413624"/>
    <dynamics damping="0.5"/>
  </joint>
  <link name="mini_servo_link_2">
    <inertial>
      <origin rpy="0 0 0" xyz="0.0 0.060 0.0"/>
      <mass value="0.050"/>
      <inertia ixx="0.005" ixy="0" ixz="0" iyy="0.005" iyz="0" izz="0.005"/>
    </inertial>
    <visual>
      <origin rpy="1.57079632679 0 1.57079632679" xyz="0 0 0"/>
      <geometry>
        <mesh filename="package://mini_servo_model/urdf/meshes/visual/link_2.stl" scale="0.001 0.001 0.001"/>
      </geometry>
      <material name="Grey"/>
    </visual>
    <collision>
      <origin rpy="1.57079632679 0 1.57079632679" xyz="0 0 0"/>
      <geometry>
        <mesh filename="package://mini_servo_model/urdf/meshes/collision/link_2.stl" scale="0.001 0.001 0.001"/>
      </geometry>
      <material name="Grey"/>
    </collision>
  </link>
  <!-- joint between link_2 and link_3 -->
  <joint name="mini_servo_joint_3" type="revolute">
    <parent link="mini_servo_link_2"/>
    <child link="mini_servo_link_3"/>
    <origin rpy="0 0 0" xyz="0 0.120 0"/>
    <axis xyz="0 0 1"/>
    <limit effort="300" lower="-1.09955742876" upper="1.16937059884" velocity="10"/>
    <safety_controller k_position="100" k_velocity="2" soft_lower_limit="-1.08210413624" soft_upper_limit="1.15191730632"/>
    <dynamics damping="0.5"/>
  </joint>
  <link name="mini_servo_link_3">
    <inertial>
      <origin rpy="0 0 0" xyz="0.030 0.020 0.0"/>
      <mass value="0.050"/>
      <inertia ixx="0.005" ixy="0" ixz="0" iyy="0.005" iyz="0" izz="0.005"/>
    </inertial>
    <visual>
      <origin rpy="-1.57079632679 0 0" xyz="0 0 0"/>
      <geometry>
        <mesh filename="package://mini_servo_model/urdf/meshes/visual/link_3.stl" scale="0.001 0.001 0.001"/>
      </geometry>
      <material name="Grey"/>
    </visual>
    <collision>
      <origin rpy="-1.57079632679 0 0" xyz="0 0 0"/>
      <geometry>
        <mesh filename="package://mini_servo_model/urdf/meshes/collision/link_3.stl" scale="0.001 0.001 0.001"/>
      </geometry>
      <material name="Grey"/>
    </collision>
  </link>
  <!-- joint between link_3 and link_4 -->
  <joint name="mini_servo_joint_4" type="revolute">
    <parent link="mini_servo_link_3"/>
    <child link="mini_servo_link_4"/>
    <origin rpy="0 -1.57079632679 0" xyz="-0.0175 0.01875 0.0"/>
    <axis xyz="0 0 1"/>
    <limit effort="300" lower="-2.00712863979" upper="1.74532925199" velocity="10"/>
    <safety_controller k_position="100" k_velocity="2" soft_lower_limit="-1.98967534727" soft_upper_limit="1.72787595947"/>
    <dynamics damping="0.5"/>
  </joint>
  <link name="mini_servo_link_4">
    <inertial>
      <origin rpy="0 0 0" xyz="0 0.067 0.034"/>
      <mass value="2.7"/>
      <inertia ixx="0.03" ixy="0" ixz="0" iyy="0.01" iyz="0" izz="0.029"/>
    </inertial>
    <visual>
      <origin rpy="-1.57079632679 0 0" xyz="0 0 0"/>
      <geometry>
        <mesh filename="package://mini_servo_model/urdf/meshes/visual/link_4.stl" scale="0.001 0.001 0.001"/>
      </geometry>
      <material name="Grey"/>
    </visual>
    <collision>
      <origin rpy="-1.57079632679 0 0" xyz="0 0 0"/>
      <geometry>
        <mesh filename="package://mini_servo_model/urdf/meshes/collision/link_4.stl" scale="0.001 0.001 0.001"/>
      </geometry>
      <material name="Grey"/>
    </collision>
  </link>
  <!-- joint between link_4 and link_5 -->
  <joint name="mini_servo_joint_5" type="revolute">
    <parent link="mini_servo_link_4"/>
    <child link="mini_servo_link_5"/>
    <origin rpy="0 -1.57079632679 3.14159265359" xyz="0 0 0.110"/>
    <axis xyz="0 0 1"/>
    <limit effort="300" lower="-1.15191730632" upper="1.95476876223" velocity="10"/>
    <safety_controller k_position="100" k_velocity="2" soft_lower_limit="-1.1344640138" soft_upper_limit="1.93731546971"/>
    <dynamics damping="0.5"/>
  </joint>
  <link name="mini_servo_link_5">
    <inertial>
      <origin rpy="0 0 0" xyz="0.0 0.0 0.055"/>
      <mass value="0.025"/>
      <inertia ixx="0.001" ixy="0" ixz="0" iyy="0.001" iyz="0" izz="0.001"/>
    </inertial>
    <visual>
      <origin rpy="-1.57079632679 0 0" xyz="0 0 0"/>
      <geometry>
        <mesh filename="package://mini_servo_model/urdf/meshes/visual/link_5.stl" scale="0.001 0.001 0.001"/>
      </geometry>
      <material name="Grey"/>
    </visual>
    <collision>
      <origin rpy="-1.57079632679 0 0" xyz="0 0 0"/>
      <geometry>
        <mesh filename="package://mini_servo_model/urdf/meshes/collision/link_5.stl" scale="0.001 0.001 0.001"/>
      </geometry>
      <material name="Grey"/>
    </collision>
  </link>
  <!-- joint between link_5 and link_6 -->
  <joint name="mini_servo_joint_6" type="revolute">
    <parent link="mini_servo_link_5"/>
    <child link="mini_servo_link_6"/>
    <origin rpy="0 1.57079632679 0" xyz="0.025 0 0"/>
    <axis xyz="0 0 1"/>
    <limit effort="300" lower="-1.36135681656" upper="2.14675497995" velocity="10"/>
    <safety_controller k_position="100" k_velocity="2" soft_lower_limit="-1.34390352404" soft_upper_limit="2.12930168743"/>
    <dynamics damping="0.5"/>
  </joint>
  <link name="mini_servo_link_6">
    <inertial>
      <origin rpy="0 0 0" xyz="0.0125 0.0 0.0"/>
      <mass value="0.010"/>
      <inertia ixx="0.001" ixy="0" ixz="0" iyy="0.001" iyz="0" izz="0.001"/>
    </inertial>
    <visual>
      <origin rpy="1.57079632679 0 0" xyz="0 0 0"/>
      <geometry>
        <mesh filename="package://mini_servo_model/urdf/meshes/visual/link_6.stl" scale="0.001 0.001 0.001"/>
      </geometry>
      <material name="Grey"/>
    </visual>
    <collision>
      <origin rpy="1.57079632679 0 0" xyz="0 0 0"/>
      <geometry>
        <mesh filename="package://mini_servo_model/urdf/meshes/collision/link_6.stl" scale="0.001 0.001 0.001"/>
      </geometry>
      <material name="Grey"/>
    </collision>
  </link>
  <joint name="mini_servo_joint_ee" type="fixed">
    <parent link="mini_servo_link_6"/>
    <child link="mini_servo_link_ee"/>
    <origin rpy="0 0 0" xyz="0 0 0.010"/>
  </joint>
  <link name="mini_servo_link_ee">
    </link>
  <!-- Load Gazebo lib and set the robot namespace -->
  <gazebo>
    <plugin filename="libgazebo_ros_control.so" name="gazebo_ros_control">
      <robotNamespace>/mini_servo</robotNamespace>
    </plugin>
  </gazebo>
  <!-- Link0 -->
  <gazebo reference="mini_servo_link_0">
    <material>Gazebo/Grey</material>
    <mu1>0.2</mu1>
    <mu2>0.2</mu2>
  </gazebo>
  <!-- Link1 -->
  <gazebo reference="mini_servo_link_1">
    <material>Gazebo/Orange</material>
    <mu1>0.2</mu1>
    <mu2>0.2</mu2>
  </gazebo>
  <!-- Link2 -->
  <gazebo reference="mini_servo_link_2">
    <material>Gazebo/Orange</material>
    <mu1>0.2</mu1>
    <mu2>0.2</mu2>
  </gazebo>
  <!-- Link3 -->
  <gazebo reference="mini_servo_link_3">
    <material>Gazebo/Orange</material>
    <mu1>0.2</mu1>
    <mu2>0.2</mu2>
  </gazebo>
  <!-- Link4 -->
  <gazebo reference="mini_servo_link_4">
    <material>Gazebo/Orange</material>
    <mu1>0.2</mu1>
    <mu2>0.2</mu2>
  </gazebo>
  <!-- Link5 -->
  <gazebo reference="mini_servo_link_5">
    <material>Gazebo/Orange</material>
    <mu1>0.2</mu1>
    <mu2>0.2</mu2>
  </gazebo>
  <!-- Link6 -->
  <gazebo reference="mini_servo_link_6">
    <material>Gazebo/Orange</material>
    <mu1>0.2</mu1>
    <mu2>0.2</mu2>
  </gazebo>
  <!-- Link7 -->
  <gazebo reference="mini_servo_link_7">
    <material>Gazebo/Grey</material>
    <mu1>0.2</mu1>
    <mu2>0.2</mu2>
  </gazebo>
  <transmission name="mini_servo_tran_1">
    <robotNamespace>/mini_servo</robotNamespace>
    <type>transmission_interface/SimpleTransmission</type>
    <joint name="mini_servo_joint_1">
      <hardwareInterface>PositionJointInterface</hardwareInterface>
    </joint>
    <actuator name="mini_servo_motor_1">
      <hardwareInterface>PositionJointInterface</hardwareInterface>
      <mechanicalReduction>1</mechanicalReduction>
    </actuator>
  </transmission>
  <transmission name="mini_servo_tran_2">
    <robotNamespace>/mini_servo</robotNamespace>
    <type>transmission_interface/SimpleTransmission</type>
    <joint name="mini_servo_joint_2">
      <hardwareInterface>PositionJointInterface</hardwareInterface>
    </joint>
    <actuator name="mini_servo_motor_2">
      <hardwareInterface>PositionJointInterface</hardwareInterface>
      <mechanicalReduction>1</mechanicalReduction>
    </actuator>
  </transmission>
  <transmission name="mini_servo_tran_3">
    <robotNamespace>/mini_servo</robotNamespace>
    <type>transmission_interface/SimpleTransmission</type>
    <joint name="mini_servo_joint_3">
      <hardwareInterface>PositionJointInterface</hardwareInterface>
    </joint>
    <actuator name="mini_servo_motor_3">
      <hardwareInterface>PositionJointInterface</hardwareInterface>
      <mechanicalReduction>1</mechanicalReduction>
    </actuator>
  </transmission>
  <transmission name="mini_servo_tran_4">
    <robotNamespace>/mini_servo</robotNamespace>
    <type>transmission_interface/SimpleTransmission</type>
    <joint name="mini_servo_joint_4">
      <hardwareInterface>PositionJointInterface</hardwareInterface>
    </joint>
    <actuator name="mini_servo_motor_4">
      <hardwareInterface>PositionJointInterface</hardwareInterface>
      <mechanicalReduction>1</mechanicalReduction>
    </actuator>
  </transmission>
  <transmission name="mini_servo_tran_5">
    <robotNamespace>/mini_servo</robotNamespace>
    <type>transmission_interface/SimpleTransmission</type>
    <joint name="mini_servo_joint_5">
      <hardwareInterface>PositionJointInterface</hardwareInterface>
    </joint>
    <actuator name="mini_servo_motor_5">
      <hardwareInterface>PositionJointInterface</hardwareInterface>
      <mechanicalReduction>1</mechanicalReduction>
    </actuator>
  </transmission>
  <transmission name="mini_servo_tran_6">
    <robotNamespace>/mini_servo</robotNamespace>
    <type>transmission_interface/SimpleTransmission</type>
    <joint name="mini_servo_joint_6">
      <hardwareInterface>PositionJointInterface</hardwareInterface>
    </joint>
    <actuator name="mini_servo_motor_6">
      <hardwareInterface>PositionJointInterface</hardwareInterface>
      <mechanicalReduction>1</mechanicalReduction>
    </actuator>
  </transmission>
</robot>

